Workbook

Sheet Sections
A1: EM Fusion literature review plan
A2: Chapter 2, 2,000 words. Counts update from the Matrix sheet as you change each source's Status.
A4: How to use this workbook
A5: • Yellow cells are yours to fill in: Status and Your notes on the Matrix sheet, Draft words here, and the Gap searches log.
A6: • Set Status as you go (To read, Read, Cited, Dropped). The counts below update automatically.
A7: • 'Checked 11 Oct 2026' means the source was found online this session; everything else is a well-known reference but still needs checking against the original before you cite it.
A8: • The Decisions sheet links your own thesis_notes.md sections to the sources that support or challenge them.
A10: § | B10: Section | C10: Absorbs your themes | D10: Target words | E10: Serves | F10: Argument this section must make | G10: Write order | H10: Sources | I10: Core sources | J10: Read or cited | K10: Draft words | L10: Words left | M10: Progress
A11: 2.1 | B11: Situational awareness in the electromagnetic environment | C11: EM situational awareness; defence digital transformation and decision advantage | D11: 350 | E11: Main RQ | F11: Awareness means perceiving and comprehending a contested environment. GNSS disruption is real and visible in open aircraft data, which makes it a credible and safe domain for this prototype. | G11: 5 | H11: =COUNTIF(Matrix!$B:$B,$A11) -> 9 | I11: =COUNTIFS(Matrix!$B:$B,$A11,Matrix!$C:$C,"Core") -> 3 | J11: =COUNTIFS(Matrix!$B:$B,$A11,Matrix!$N:$N,"Read")+COUNTIFS(Matrix!$B:$B,$A11,Matrix!$N:$N,"Cited") -> 0 | K11: 0 | L11: =D11-K11 -> 350 | M11: =IFERROR(J11/H11,0) -> 0
A12: 2.2 | B12: Data fusion, abstraction and provenance | C12: Data fusion and DALs; geospatial and time-series systems (one paragraph at most) | D12: 400 | E12: RQ1 | F12: Fusing disparate sources is a long-standing problem. A fixed canonical model with per-source adapters keeps adding a source local, and provenance has to be checked rather than assumed. | G12: 3 | H12: =COUNTIF(Matrix!$B:$B,$A12) -> 10 | I12: =COUNTIFS(Matrix!$B:$B,$A12,Matrix!$C:$C,"Core") -> 5 | J12: =COUNTIFS(Matrix!$B:$B,$A12,Matrix!$N:$N,"Read")+COUNTIFS(Matrix!$B:$B,$A12,Matrix!$N:$N,"Cited") -> 0 | K12: 0 | L12: =D12-K12 -> 400 | M12: =IFERROR(J12/H12,0) -> 0
A13: 2.3 | B13: Detecting anomalies in telemetry, and evaluating detectors | C13: Anomaly detection | D13: 400 | E13: RQ2 | F13: Detector sophistication matters less than trustworthy ground truth and honestly defined metrics, which justifies synthetic scenarios and deterministic rules. | G13: 1 | H13: =COUNTIF(Matrix!$B:$B,$A13) -> 6 | I13: =COUNTIFS(Matrix!$B:$B,$A13,Matrix!$C:$C,"Core") -> 3 | J13: =COUNTIFS(Matrix!$B:$B,$A13,Matrix!$N:$N,"Read")+COUNTIFS(Matrix!$B:$B,$A13,Matrix!$N:$N,"Cited") -> 0 | K13: 0 | L13: =D13-K13 -> 400 | M13: =IFERROR(J13/H13,0) -> 0
A14: 2.4 | B14: Humans, explanations and grounded generation | C14: Human-in-the-loop AI; explainable AI | D14: 450 | E14: RQ3 | F14: Explanations can increase over-reliance. Safe decision support needs calibrated confidence, contrastive alternatives and grounding in identified evidence, and grounding can only be partly checked by machine. | G14: 2 | H14: =COUNTIF(Matrix!$B:$B,$A14) -> 13 | I14: =COUNTIFS(Matrix!$B:$B,$A14,Matrix!$C:$C,"Core") -> 7 | J14: =COUNTIFS(Matrix!$B:$B,$A14,Matrix!$N:$N,"Read")+COUNTIFS(Matrix!$B:$B,$A14,Matrix!$N:$N,"Cited") -> 0 | K14: 0 | L14: =D14-K14 -> 450 | M14: =IFERROR(J14/H14,0) -> 0
A15: 2.5 | B15: Assuring AI in defence | C15: AI assurance; responsible defence AI | D15: 250 | E15: RQ3, ethics | F15: Defence AI principles are clearly stated but thin on mechanisms; EM Fusion turns several of them into testable safeguards. | G15: 4 | H15: =COUNTIF(Matrix!$B:$B,$A15) -> 7 | I15: =COUNTIFS(Matrix!$B:$B,$A15,Matrix!$C:$C,"Core") -> 3 | J15: =COUNTIFS(Matrix!$B:$B,$A15,Matrix!$N:$N,"Read")+COUNTIFS(Matrix!$B:$B,$A15,Matrix!$N:$N,"Cited") -> 0 | K15: 0 | L15: =D15-K15 -> 250 | M15: =IFERROR(J15/H15,0) -> 0
A16: 2.6 | B16: Synthesis and gap | C16: (none: ties the sections together) | D16: 150 | E16: All | F16: Return to Endsley and JDL, then state the gap (draft below) and how RQ1–RQ3 address it. | G16: 6 | H16: =COUNTIF(Matrix!$B:$B,$A16) -> 0 | I16: =COUNTIFS(Matrix!$B:$B,$A16,Matrix!$C:$C,"Core") -> 0 | J16: =COUNTIFS(Matrix!$B:$B,$A16,Matrix!$N:$N,"Read")+COUNTIFS(Matrix!$B:$B,$A16,Matrix!$N:$N,"Cited") -> 0 | K16: 0 | L16: =D16-K16 -> 150 | M16: =IFERROR(J16/H16,0) -> 0
B17: Total | D17: =SUM(D11:D16) -> 2000 | H17: =SUM(H11:H16) -> 45 | I17: =SUM(I11:I16) -> 21 | J17: =SUM(J11:J16) -> 0 | K17: =SUM(K11:K16) -> 0 | L17: =SUM(L11:L16) -> 2000 | M17: =IFERROR(J17/H17,0) -> 0
A19: Draft gap statement (rewrite in your own words; confirm the 'little published work' claim with the Gap searches log)
A20: Prior work detects GNSS interference from aircraft integrity fields (Liu, Lo and Walter, 2022; Felux et al., 2023), and separately studies how to ground language-model output in identified sources (Rashkin et al., 2023; Gao et al., 2023). Little published work combines a canonical data abstraction layer, deterministic detection evaluated against known ground truth, and evidence-constrained hypothesis generation assessed for grounding, under defence AI assurance guidance (MoD, 2024).

Sheet Matrix
A1: ID | B1: Section | C1: Priority | D1: Reference (Harvard) | E1: Year | F1: Type | G1: Checked? | H1: Key claim | I1: Method / evidence | J1: Limitation or tension | K1: So what for EM Fusion | L1: Your notes that it supports (thesis_notes.md) | M1: RQ | N1: Status | O1: Your notes | P1: Link
A2: S01 | B2: 2.1 | C2: Core | D2: Endsley, M.R. (1995) 'Toward a theory of situation awareness in dynamic systems', Human Factors, 37(1), pp. 32–64. | E2: 1995 | F2: Journal | G2: Verify details | H2: Situation awareness has three levels: perception of elements in the environment, comprehension of their meaning, and projection of their future status. | I2: Theoretical model built from aviation and military human-factors research. | J2: Models one person's cognition; distributed/team SA critics (see S02) argue it underplays how awareness is shared across people and systems. Measuring SA is contested. | K2: The spine of the whole review. DAL and canonical observations support perception; detection, evidence bundles and hypotheses support comprehension; EM Fusion deliberately stops before projection and leaves it to the analyst. Introduce in 2.1, return to it in 2.6. | L2: thesis_notes: An aircraft's state is a lookup into stored findings, with three values and a deliberately mild word | M2: Main RQ | N2: To read
A3: S02 | B3: 2.1 | C3: Optional | D3: Stanton, N.A. et al. (2006) 'Distributed situation awareness in dynamic systems: theoretical development and application of an ergonomics methodology', Ergonomics, 49(12–13), pp. 1288–1311. | E3: 2006 | F3: Journal | G3: Verify details | H3: Situation awareness is distributed across people and artefacts in a system rather than held only in individual heads. | I3: Theoretical development plus applied ergonomics methodology. | J3: Harder to operationalise than Endsley's model; less used in software design. | K3: One sentence of critical tension on Endsley: EM Fusion is itself an artefact that holds part of the awareness (stored findings, provenance), which is a distributed-SA reading of the system. | M3: Main RQ | N3: To read
A4: S03 | B4: 2.1 | C4: Core | D4: Felux, M., Figuet, B., Waltert, M., Fol, P., Strohmeier, M. and Olive, X. (2023) 'Analysis of GNSS disruptions in European airspace', in Proceedings of the 2023 International Technical Meeting of The Institute of Navigation (ION ITM). Long Beach, CA, pp. 315–326. doi:10.33012/2023.18626. | E4: 2023 | F4: Conference | G4: Checked 11 Oct 2026 | H4: GNSS disruption affecting civil aircraft across European airspace can be observed and analysed in crowdsourced ADS-B data. | I4: Large-scale analysis of ADS-B data; authors include members of the OpenSky team. Read the paper to confirm which ADS-B fields they rely on. | J4: Civil-aviation lens; likely depends on integrity fields that OpenSky's state vectors do not carry. | K4: Your strongest motivation source: GNSS disruption is real, current, and visible in the same family of open data as your replay corpus. Use it to justify the domain as both credible and safe (open data only). | L4: thesis_notes: The staged track signature sits inside the corpus's own background, and no threshold separates them | M4: Main RQ, RQ2 | N4: To read | P4: https://www.cs.ox.ac.uk/publications/publication15799-abstract.html
A5: S04 | B5: 2.1 | C5: Supporting | D5: Figuet, B. et al. (2022) 'GNSS jamming and its effect on air traffic in Eastern Europe', Engineering Proceedings. [Verify full author list, volume and article number.] | E5: 2022 | F5: Conference | G5: Checked 11 Oct 2026 (exists; details to verify) | H5: GNSS jamming has a measurable effect on air traffic in Eastern Europe, visible in ADS-B data. | I5: Regional empirical analysis of aircraft surveillance data. | J5: Single-region case study. | K5: Second empirical anchor alongside S03; shows the problem is regional and ongoing, not hypothetical. | M5: Main RQ | N5: To read | P5: https://digitalcollection.zhaw.ch/handle/11475/26900
A6: S05 | B6: 2.1 | C6: Core | D6: Liu, Z., Lo, S. and Walter, T. (2022) 'GNSS interference source localization using ADS-B data', in Proceedings of the 2022 International Technical Meeting of The Institute of Navigation (ION ITM). [Verify venue and pages.] | E6: 2022 | F6: Conference | G6: Checked 11 Oct 2026 | H6: GNSS interference sources can be localised from the ADS-B Navigation Integrity Category (NIC): positions with NIC below 7 are treated as affected, and a Bayesian grid search estimates jammer location and power. | I6: ADS-B NIC values plus aircraft position and altitude. | J6: Depends on NIC, which OpenSky state vectors do not include. Localises a source; does not explain alternatives such as coverage loss. | K6: The established technique uses integrity fields. EM Fusion's aircraft side has only update gaps / contact staleness, a weaker proxy that overlaps with ordinary coverage loss. Name this contrast explicitly: it is a strength of the review and the honest root of your coverage-gap limitation. | L6: thesis_notes: The staged track signature sits inside the corpus's own background…; Limitation: the aircraft-coverage-gap arm has no positive rule | M6: RQ2 | N6: To read | P6: https://web.stanford.edu/group/scpnt/gpslab/pubs/papers/Liu_ION_ITM_2022_ADSB.pdf
A7: S06 | B7: 2.1 | C7: Supporting | D7: Schäfer, M., Strohmeier, M., Lenders, V., Martinovic, I. and Wilhelm, M. (2014) 'Bringing up OpenSky: a large-scale ADS-B sensor network for research', in Proceedings of the 13th International Symposium on Information Processing in Sensor Networks (IPSN). IEEE, pp. 83–94. [Verify pages.] | E7: 2014 | F7: Conference | G7: Verify details | H7: OpenSky is a crowdsourced ADS-B receiver network that makes aircraft surveillance data available for research. | I7: System description and network characterisation. | J7: Coverage depends on volunteer receivers, so gaps in the data are not evidence of interference. | K7: Provenance of your replay corpus. Its uneven coverage is exactly why the coverage-gap scenario exists: a gap caused by no receiver nearby must not be read as jamming. | L7: thesis_notes: Data acquisition: OpenSky static snapshot rather than the Trino interface; Bounding box: 49–54°N, 3–11°E | M7: RQ1, RQ2 | N7: To read | P7: https://opensky-network.org
A8: S07 | B8: 2.1 | C8: Supporting | D8: Ministry of Defence (2025) The Strategic Defence Review 2025 – Making Britain Safer: secure at home, strong abroad. London: MoD. | E8: 2025 | F8: Official document | G8: Checked 11 Oct 2026 | H8: Describes a changed threat environment and calls for modernised capability, including cyber and electromagnetic capability. | I8: Government policy review. | J8: Policy statement, not evidence. Easy to over-quote. | K8: Context. Carry it mainly in the Introduction; one or two sentences in 2.1 at most. | M8: Main RQ | N8: To read | P8: https://www.gov.uk/government/publications/the-strategic-defence-review-2025-making-britain-safer-secure-at-home-strong-abroad
A9: S08 | B9: 2.1 | C9: Optional | D9: Development, Concepts and Doctrine Centre (2018) Joint Concept Note 2/18: Information Advantage. Shrivenham: DCDC. [Verify title and date.] | E9: 2018 | F9: Official document | G9: Verify details | H9: Frames information advantage as a UK military concept: gaining advantage through the use and exploitation of information. | I9: Doctrine / concept note. | J9: Concept-level; not about software or data systems specifically. | K9: Grounds 'decision advantage' in UK doctrine instead of marketing language. Use if 2.1 needs a definition of the term. | M9: Main RQ | N9: To read
A10: S09 | B10: 2.1 | C10: Optional | D10: Department of Defense (2020) Electromagnetic Spectrum Superiority Strategy. Washington, DC: DoD. [Verify.] | E10: 2020 | F10: Official document | G10: Verify details | H10: Treats the electromagnetic spectrum as a contested domain where awareness and superiority are strategic priorities. | I10: National strategy document. | J10: US, not UK. High-level. | K10: Shows allied doctrine prioritises EM spectrum awareness. Use only if UK sources are thin. | M10: Main RQ | N10: To read
A11: S10 | B11: 2.2 | C11: Core | D11: Hall, D.L. and Llinas, J. (1997) 'An introduction to multisensor data fusion', Proceedings of the IEEE, 85(1), pp. 6–23. | E11: 1997 | F11: Journal | G11: Verify details | H11: Multisensor fusion combines data from several sources to reach inferences that no single source supports; introduces the JDL process model to a wider audience. | I11: Tutorial / survey. | J11: Pre-dates modern data platforms and machine learning; sensor-centric. | K11: Defines fusion. Justifies why RF plus aircraft evidence together can say more than either alone, which your sensor-fault and mixed-evidence arms test directly. | L11: thesis_notes: The five scenario types span a confusion space rather than enumerate faults | M11: RQ1 | N11: To read
A12: S11 | B12: 2.2 | C12: Core | D12: Steinberg, A.N., Bowman, C.L. and White, F.E. (1999) 'Revisions to the JDL data fusion model', in Proceedings of SPIE 3719, Sensor Fusion: Architectures, Algorithms, and Applications III. | E12: 1999 | F12: Conference | G12: Verify details | H12: Revises the JDL levels (0 sub-object, 1 object, 2 situation, 3 impact, 4 process refinement) and broadens them beyond military use. | I12: Conceptual revision of a reference model. | J12: The levels are often misread as a processing pipeline or architecture. | K12: Place your pipeline on it: adapters/DAL ≈ Levels 0–1; rule ladder and evidence bundles ≈ Level 2 situation assessment; impact assessment (Level 3) deliberately out of scope. | M12: RQ1 | N12: To read
A13: S12 | B13: 2.2 | C13: Core | D13: Blasch, E.P. and Plano, S. (2002) 'JDL Level 5 fusion model: user refinement issues and applications in group tracking', in Proceedings of SPIE 4729. [Verify.] | E13: 2002 | F13: Conference | G13: Verify details | H13: Adds Level 5, 'user refinement': the human is part of the fusion process, guiding and validating it. | I13: Conceptual extension with application examples. | J13: Conceptual; few empirical evaluations. | K13: Your analyst-verdict loop is Level 5 in the fusion field's own vocabulary. Lets you argue human-in-the-loop is a fusion design principle, not a bolt-on. | M13: RQ1, RQ3 | N13: To read
A14: S13 | B14: 2.2 | C14: Supporting | D14: Khaleghi, B., Khamis, A., Karray, F.O. and Razavi, S.N. (2013) 'Multisensor data fusion: a review of the state-of-the-art', Information Fusion, 14(1), pp. 28–44. | E14: 2013 | F14: Journal | G14: Verify details | H14: Organises fusion challenges by data imperfection, correlation, inconsistency (conflict, outliers) and disparateness. | I14: Survey. | J14: Algorithm-focused; little on software architecture. | K14: 'Inconsistency' maps to your mixed-evidence arm and to bundles that carry rejected competing claims; 'disparateness' is the case for a canonical model. | L14: thesis_notes: The safeguard's hardest case is created by the bundle's own honesty | M14: RQ1 | N14: To read
A15: S14 | B15: 2.2 | C15: Core | D15: Lenzerini, M. (2002) 'Data integration: a theoretical perspective', in Proceedings of the 21st ACM Symposium on Principles of Database Systems (PODS). ACM, pp. 233–246. | E15: 2002 | F15: Conference | G15: Verify details | H15: Integration through a global schema and source mappings; global-as-view (GAV) makes querying simple, local-as-view (LAV) makes adding a source simple. | I15: Formal theory of data integration. | J15: Theory of virtual integration; EM Fusion materialises data (ETL-style). Say so. | K15: The theoretical frame for the DAL and RQ1: the canonical model stays fixed and each source is described against it, so a new source is a new adapter. Your measured extensibility result is evidence for that property. | L15: thesis_notes: The extensibility claim, measured rather than asserted; A second canonical shape, and a prediction worth scoring | M15: RQ1 | N15: To read
A16: S15 | B16: 2.2 | C16: Supporting | D16: Hohpe, G. and Woolf, B. (2003) Enterprise Integration Patterns: Designing, Building, and Deploying Messaging Solutions. Boston: Addison-Wesley. | E16: 2003 | F16: Book | G16: Verify details | H16: Canonical Data Model pattern: translating each system to one shared model needs about 2n translators instead of n(n−1) point-to-point ones. | I16: Practitioner pattern catalogue. | J16: Not empirical. Canonical models can bloat into a lowest-common-denominator schema. | K16: The software-engineering name and cost argument for your DAL. Pair with S14 (theory) for a practice-plus-theory paragraph. | M16: RQ1 | N16: To read
A17: S16 | B17: 2.2 | C17: Core | D17: Buneman, P., Khanna, S. and Tan, W.-C. (2001) 'Why and where: a characterization of data provenance', in Database Theory – ICDT 2001. LNCS 1973. Berlin: Springer, pp. 316–330. | E17: 2001 | F17: Conference | G17: Verify details | H17: Distinguishes why-provenance (which source data justify a result) from where-provenance (where a value was copied from). | I17: Formal characterisation. | J17: Database-theoretic; does not address ML or generated text. | K17: Evidence-bundle citations are why-provenance for a hypothesis. Your finding that one cited coordinate in eleven resolved to nothing shows provenance must be verified, not assumed. | L17: thesis_notes: The first time every citation was checked, one in eleven pointed at nothing; Explainability has a storage problem before it has an interface problem | M17: RQ1, RQ3 | N17: To read
A18: S17 | B18: 2.2 | C18: Supporting | D18: Moreau, L. and Missier, P. (eds) (2013) PROV-DM: The PROV Data Model. W3C Recommendation. | E18: 2013 | F18: Standard | G18: Verify details | H18: Entity–activity–agent model for recording and exchanging provenance. | I18: Standards specification. | J18: Interchange model; you do not implement it. | K18: Justifies the provenance fields on the canonical observation; one sentence noting how they map to PROV concepts is enough. | M18: RQ1 | N18: To read | P18: https://www.w3.org/TR/prov-dm/
A19: S18 | B19: 2.2 | C19: Supporting | D19: Wang, R.Y. and Strong, D.M. (1996) 'Beyond accuracy: what data quality means to data consumers', Journal of Management Information Systems, 12(4), pp. 5–33. | E19: 1996 | F19: Journal | G19: Verify details | H19: Data quality is multidimensional from the consumer's view: intrinsic, contextual, representational and accessibility dimensions. | I19: Survey of data consumers plus factor analysis. | J19: Business-information context; dated. | K19: Justifies validation and quarantine (intrinsic quality) and showing data mode and absence honestly (representational quality). | L19: thesis_notes: Absence is served as absence: null rather than a neutral reading; The ERD had no home for a quarantined record | M19: RQ1 | N19: To read
A20: S19 | B20: 2.2 | C20: Optional | D20: Ministry of Defence (2021) Data Strategy for Defence. London: MoD. [Verify title and date.] | E20: 2021 | F20: Official document | G20: Verify details | H20: Treats data as a strategic asset and calls for common standards and interoperability. | I20: Departmental strategy. | J20: Policy aspiration, not evidence. | K20: Organisational motivation for a canonical model in a defence setting. One sentence. | M20: RQ1 | N20: To read
A21: S20 | B21: 2.3 | C21: Core | D21: Chandola, V., Banerjee, A. and Kumar, V. (2009) 'Anomaly detection: a survey', ACM Computing Surveys, 41(3), Article 15. | E21: 2009 | F21: Journal | G21: Verify details | H21: Taxonomy of point, contextual and collective anomalies, and of detection techniques by category. | I21: Survey. | J21: Pre-dates deep learning; says little about evaluation. | K21: Your anomalies are contextual (an RF reading unusual against its baseline) and collective (a cluster of track gaps), which favours baseline-relative rules over global outlier scores. | M21: RQ2 | N21: To read
A22: S21 | B22: 2.3 | C22: Supporting | D22: Blázquez-García, A., Conde, A., Mori, U. and Lozano, J.A. (2021) 'A review on outlier/anomaly detection in time series data', ACM Computing Surveys, 54(3), Article 56. | E22: 2021 | F22: Journal | G22: Verify details | H22: Organises time-series outlier detection by point vs subsequence and univariate vs multivariate. | I22: Survey. | J22: Method taxonomy; does not settle which methods work best. | K22: Positions your per-sensor, per-channel baselines as univariate contextual detection. Documents the field's shift toward learned models, which S22–S24 then question. | L22: thesis_notes: RF observation model: a sensor × channel grid rather than per-sensor readings | M22: RQ2 | N22: To read
A23: S22 | B23: 2.3 | C23: Core | D23: Wu, R. and Keogh, E.J. (2023) 'Current time series anomaly detection benchmarks are flawed and are creating the illusion of progress', IEEE Transactions on Knowledge and Data Engineering. [arXiv 2020; verify year, volume and pages of published version.] | E23: 2023 | F23: Journal | G23: Checked 11 Oct 2026 (arXiv) | H23: Widely used benchmarks are flawed by triviality (one-line solutions), unrealistic anomaly density, mislabelled ground truth and run-to-failure bias. | I23: Critical analysis of public benchmark datasets. | J23: Targets univariate benchmarks; authors propose their own archive. | K23: Justifies synthetic scenarios with generator-side ground truth and simple detectors: credibility comes from trustworthy labels, not detector sophistication. | L23: thesis_notes: Ground truth is generator-side only | M23: RQ2 | N23: To read | O23: (example) Read §3 on triviality and §4 on mislabelling. Quote the 'one line of code' point in 2.3. | P23: https://arxiv.org/abs/2009.13807v3
A24: S23 | B24: 2.3 | C24: Core | D24: Kim, S., Choi, K., Choi, H.-S., Lee, B. and Yoon, S. (2022) 'Towards a rigorous evaluation of time-series anomaly detection', in Proceedings of the AAAI Conference on Artificial Intelligence, 36(7), pp. 7194–7201. [Verify pages.] | E24: 2022 | F24: Conference | G24: Checked 11 Oct 2026 | H24: The common point-adjustment protocol inflates F1 so much that random anomaly scores can look competitive; proposes a stricter evaluation. | I24: Analytical and empirical critique of evaluation protocols. | J24: Focused on learned detectors on public benchmarks. | K24: Justifies defining metrics before measuring and not adjusting them afterwards. Supports your pre-registration and your careful latency definition. | L24: thesis_notes: Detection latency: defining a delay in a system that has no moment of noticing; Pre-registering the replication before running it | M24: RQ2 | N24: To read | P24: https://ojs.aaai.org/index.php/AAAI/article/view/20680
A25: S24 | B25: 2.3 | C25: Supporting | D25: Schmidl, S., Wenig, P. and Papenbrock, T. (2022) 'Anomaly detection in time series: a comprehensive evaluation', Proceedings of the VLDB Endowment, 15(9), pp. 1779–1797. | E25: 2022 | F25: Journal | G25: Verify details | H25: Across 71 algorithms on about 1,000 series, no method wins everywhere and classical methods are often competitive with deep learning. | I25: Large comparative benchmark. | J25: Results depend on the benchmark collection used. | K25: Supports the choice of deterministic rules: there is no evidence a complex detector would have been better, and rules can be cited as evidence. | M25: RQ2 | N25: To read
A26: S25 | B26: 2.3 | C26: Optional | D26: Liu, F.T., Ting, K.M. and Zhou, Z.-H. (2008) 'Isolation forest', in Proceedings of the 8th IEEE International Conference on Data Mining (ICDM). IEEE, pp. 413–422. | E26: 2008 | F26: Conference | G26: Verify details | H26: Isolates anomalies by random partitioning; efficient and unsupervised. | I26: Algorithm proposal and experiments. | J26: Produces a score without a human-readable rule. | K26: Cite only to explain why it was set aside: an unsupervised score is hard to put in an evidence bundle as a citable finding. | M26: RQ2 | N26: To read
A27: S26 | B27: 2.4 | C27: Core | D27: Parasuraman, R., Sheridan, T.B. and Wickens, C.D. (2000) 'A model for types and levels of human interaction with automation', IEEE Transactions on Systems, Man, and Cybernetics – Part A, 30(3), pp. 286–297. | E27: 2000 | F27: Journal | G27: Verify details | H27: Automation applies to four stages (information acquisition, information analysis, decision selection, action implementation), each at its own level. | I27: Conceptual model. | J27: Pre-dates generative AI; levels are coarse. | K27: States EM Fusion's position precisely: it automates acquisition and analysis, and deliberately not decision selection or action. | M27: RQ3 | N27: To read
A28: S27 | B28: 2.4 | C28: Supporting | D28: Parasuraman, R. and Riley, V. (1997) 'Humans and automation: use, misuse, disuse, abuse', Human Factors, 39(2), pp. 230–253. | E28: 1997 | F28: Journal | G28: Verify details | H28: Distinguishes use, misuse (over-reliance), disuse (under-reliance) and abuse of automation. | I28: Review and conceptual analysis. | J28: Pre-AI; examples from aviation and process control. | K28: Names the risk your design guards against: misuse, an analyst accepting a hypothesis because the system produced it. | M28: RQ3 | N28: To read
A29: S28 | B29: 2.4 | C29: Core | D29: Lee, J.D. and See, K.A. (2004) 'Trust in automation: designing for appropriate reliance', Human Factors, 46(1), pp. 50–80. | E29: 2004 | F29: Journal | G29: Verify details | H29: The goal is calibrated trust, reliance that matches the system's real capability; showing purpose, process and performance supports calibration. | I29: Integrative review. | J29: Trust measurement varies across studies. | K29: Justifies Low/Medium/High instead of fake precision, mild wording, and showing uncertainty and alternatives beside every hypothesis. | L29: thesis_notes: The contract violated the project's own no-fake-precision rule…; An aircraft's state is a lookup into stored findings, with three values and a deliberately mild word | M29: RQ3 | N29: To read
A30: S29 | B30: 2.4 | C30: Supporting | D30: Cummings, M.L. (2004) 'Automation bias in intelligent time critical decision support systems', in AIAA 1st Intelligent Systems Technical Conference. Chicago, IL. [Verify.] | E30: 2004 | F30: Conference | G30: Verify details | H30: Under time pressure, operators tend to accept automated recommendations, producing errors of commission and omission. | I30: Review with defence and aviation examples. | J30: Conference paper; argument more than new data. | K30: Time pressure is your use case. Motivates showing evidence before conclusions and keeping the human verdict explicit. | M30: RQ3 | N30: To read
A31: S30 | B31: 2.4 | C31: Core | D31: Bansal, G. et al. (2021) 'Does the whole exceed its parts? The effect of AI explanations on complementary team performance', in Proceedings of the 2021 CHI Conference on Human Factors in Computing Systems. ACM. | E31: 2021 | F31: Conference | G31: Verify details | H31: AI explanations increased acceptance of AI recommendations whether or not they were correct, and did not beat simply showing confidence. | I31: Controlled user studies. | J31: Lab tasks, not operational analysts. | K31: Your strongest argument that fluent explanations are a risk, not just a benefit. Justifies a grounding check and blind scoring of evidence fidelity over persuasiveness, and the honest template baseline. | L31: thesis_notes: A baseline that cannot flatter itself, and the two jobs that shape it | M31: RQ3 | N31: To read
A32: S31 | B32: 2.4 | C32: Supporting | D32: Buçinca, Z., Malaya, M.B. and Gajos, K.Z. (2021) 'To trust or to think: cognitive forcing functions can reduce overreliance on AI in AI-assisted decision-making', Proceedings of the ACM on Human-Computer Interaction, 5(CSCW1), Article 188. | E32: 2021 | F32: Journal | G32: Verify details | H32: Cognitive forcing functions reduce over-reliance on AI, but users like them less. | I32: Controlled experiments. | J32: Lab setting; trade-off between accuracy and user preference. | K32: Asking for an explicit verdict and showing alternatives is a mild forcing function. Because the user study was withdrawn, its effect is untested: say so. | L32: thesis_notes: Evaluation design: withdrawing the task-based user study, retaining blind rubric scoring | M32: RQ3 | N32: To read
A33: S32 | B33: 2.4 | C33: Core | D33: Miller, T. (2019) 'Explanation in artificial intelligence: insights from the social sciences', Artificial Intelligence, 267, pp. 1–38. | E33: 2019 | F33: Journal | G33: Verify details | H33: Human explanations are contrastive (why P rather than Q), selective and social; causes matter more to people than probabilities. | I33: Review of philosophy, psychology and cognitive science. | J33: Mostly about explaining model decisions, not generated hypotheses. | K33: Alternative explanations and the rejected competing claims carried in each bundle make your hypotheses contrastive. Also supports categorical confidence over numbers. | L33: thesis_notes: The safeguard's hardest case is created by the bundle's own honesty | M33: RQ3 | N33: To read
A34: S33 | B34: 2.4 | C34: Supporting | D34: Doshi-Velez, F. and Kim, B. (2017) 'Towards a rigorous science of interpretable machine learning', arXiv:1702.08608. | E34: 2017 | F34: Preprint | G34: Verify details | H34: Interpretability can be evaluated in three ways: application-grounded, human-grounded and functionally-grounded. | I34: Position paper. | J34: Preprint; a taxonomy, not evidence. | K34: Places your evaluation cleanly: detection metrics and the grounding check are functionally-grounded; the blind rubric is human-grounded; the withdrawn user study would have been application-grounded. A neat way to state the gap in 2.6. | L34: thesis_notes: Evaluation design: withdrawing the task-based user study, retaining blind rubric scoring | M34: RQ3 | N34: To read
A35: S34 | B35: 2.4 | C35: Core | D35: Ji, Z. et al. (2023) 'Survey of hallucination in natural language generation', ACM Computing Surveys, 55(12), Article 248. | E35: 2023 | F35: Journal | G35: Verify details | H35: Hallucination is intrinsic (contradicts the source) or extrinsic (cannot be verified from the source). | I35: Survey. | J35: Covers many tasks; mitigation results vary by task. | K35: Your grounding check targets fabricated references (extrinsic); misdescribed references (intrinsic) are left to the rubric. This is the vocabulary for that limitation. | L35: thesis_notes: Threat to validity: the grounding check resolves identifiers, not sentences | M35: RQ3 | N35: To read
A36: S35 | B36: 2.4 | C36: Core | D36: Rashkin, H. et al. (2023) 'Measuring attribution in natural language generation models', Computational Linguistics, 49(4), pp. 777–840. | E36: 2023 | F36: Journal | G36: Verify details | H36: Attributable to Identified Sources (AIS): output counts as attributable if a generic reader would agree the identified sources support it; defines a human-annotation protocol. | I36: Framework plus annotation studies. | J36: Human judgement is expensive; automatic proxies are imperfect. | K36: Closest relative of your grounding check. AIS judges sentences; your check resolves identifiers, so your catch rate is a lower bound on ungroundedness. Your rubric's evidence-fidelity dimension is a small AIS-style human judgement. | L36: thesis_notes: Threat to validity: the grounding check resolves identifiers, not sentences | M36: RQ3 | N36: To read
A37: S36 | B37: 2.4 | C37: Core | D37: Gao, T., Yen, H., Yu, J. and Chen, D. (2023) 'Enabling large language models to generate text with citations', in Proceedings of the 2023 Conference on Empirical Methods in Natural Language Processing (EMNLP). ACL. [Verify pages.] | E37: 2023 | F37: Conference | G37: Verify details | H37: ALCE benchmark: LLM answers with citations, with citation recall and precision measured automatically using entailment; models often lack full citation support. | I37: Benchmark and evaluation. | J37: Open-domain QA, not decision support. | K37: Shows the field measures citation support at sentence level. Contrast with your exact-identifier matching and justify the choice: exact, auditable, no model judging a model. | L37: thesis_notes: Matching is exact, and a near miss is recorded rather than forgiven | M37: RQ3 | N37: To read
A38: S37 | B38: 2.4 | C38: Supporting | D38: Lewis, P. et al. (2020) 'Retrieval-augmented generation for knowledge-intensive NLP tasks', in Advances in Neural Information Processing Systems 33 (NeurIPS 2020), pp. 9459–9474. | E38: 2020 | F38: Conference | G38: Verify details | H38: Combining a language model with retrieved documents improves factual, knowledge-intensive generation. | I38: Model architecture plus benchmarks. | J38: Retrieval can still surface wrong or irrelevant material. | K38: Frame the evidence bundle as constrained retrieval: deterministic rules choose the evidence, so the model never searches and cannot pull in anything unvetted. | M38: RQ3 | N38: To read
A39: S38 | B39: 2.4 | C39: Supporting | D39: Ouyang, S., Zhang, J.M., Harman, M. and Wang, M. (2025) 'An empirical study of the non-determinism of ChatGPT in code generation', ACM Transactions on Software Engineering and Methodology. [Verify volume/issue; arXiv 2308.02828.] | E39: 2025 | F39: Journal | G39: Checked 11 Oct 2026 | H39: LLM outputs vary substantially across repeated requests, even at temperature 0. | I39: Empirical study over code-generation benchmarks. | J39: Code generation, not explanation; model versions change. | K39: Backs your own finding that the provider was not deterministic at temperature 0 with a fixed seed, and justifies N = 3 generations per bundle. | L39: thesis_notes: The provider is not deterministic at temperature 0 with a fixed seed; Raising N from one to three… | M39: RQ3 | N39: To read | P39: https://arxiv.org/abs/2308.02828
A40: S39 | B40: 2.5 | C40: Core | D40: Ministry of Defence (2024) JSP 936: Dependable Artificial Intelligence (AI) in Defence. Part 1: Directive. London: MoD. | E40: 2024 | F40: Official document | G40: Checked 11 Oct 2026 | H40: Directive for assuring AI-enabled systems across their lifecycle in UK defence, built on the MoD's AI ethics principles. | I40: Departmental directive. | J40: Written for MoD programmes; your prototype is not formally assured under it. | K40: The governing UK document. Map your safeguards to its principles: understanding → evidence and provenance; reliability → grounding check and fallbacks; human-centricity and responsibility → the analyst verdict. | L40: thesis_notes: Two failure categories, because two fallbacks must not become one | M40: RQ3 | N40: To read | P40: https://www.gov.uk/government/publications/jsp-936-dependable-artificial-intelligence-ai-in-defence-part-1-directive
...

Sheet Decisions
A1: Your decision or finding (thesis_notes.md heading) | B1: Notes chapter | C1: Sources (Matrix IDs) | D1: Use the source to… | E1: Lit review section | F1: Sentence starter (rewrite in your own words)
A2: Ground truth is generator-side only | B2: Methodology | C2: S22, S23 | D2: Support | E2: 2.3 | F2: Because widely used benchmarks have been shown to carry mislabelled or leaky ground truth (Wu and Keogh), EM Fusion records ground truth only on the generator side…
A3: The five scenario types span a confusion space rather than enumerate faults | B3: System Design | C3: S13, S20, S10 | D3: Support | E3: 2.3 | F3: Conflicting evidence is a recognised fusion challenge (Khaleghi et al.), so the scenarios include cases built to tempt a false interference claim…
A4: The staged track signature sits inside the corpus's own background, and no threshold separates them | B4: Implementation | C4: S05, S03, S06 | D4: Contrast and limitation | E4: 2.1 / 2.3 | F4: Published approaches detect interference from ADS-B integrity fields (Liu, Lo and Walter); the open state vectors used here carry only update timing, which overlaps with ordinary coverage loss…
A5: Limitation: the aircraft-coverage-gap arm has no positive rule | B5: Evaluation | C5: S06, S05 | D5: Limitation | E5: 2.3 (and Discussion) | F5: Crowdsourced receiver networks have uneven coverage (Schäfer et al.), so silence is not evidence of interference…
A6: The extensibility claim, measured rather than asserted | B6: Implementation | C6: S14, S15 | D6: Support | E6: 2.2 | F6: Integration theory distinguishes designs where adding a source is local from those where it is not (Lenzerini); RQ1 measures which one the DAL achieves…
A7: The first time every citation was checked, one in eleven pointed at nothing | B7: Implementation | C7: S16, S17 | D7: Support | E7: 2.2 | F7: Provenance research separates where a value came from and why a result holds (Buneman, Khanna and Tan); EM Fusion checks the second rather than assuming it…
A8: Absence is served as absence: null rather than a neutral reading; The ERD had no home for a quarantined record | B8: System Design / Implementation | C8: S18 | D8: Support | E8: 2.2 | F8: Data quality has representational as well as intrinsic dimensions (Wang and Strong), so missing data is shown as missing…
A9: The contract violated the project's own no-fake-precision rule… | B9: System Design | C9: S28, S32 | D9: Support | E9: 2.4 | F9: Appropriate reliance depends on calibrated trust (Lee and See); a generated '87%' invites an analyst to treat a guess as a measurement…
A10: An aircraft's state is a lookup into stored findings, with three values and a deliberately mild word | B10: System Design | C10: S28, S27, S29 | D10: Support | E10: 2.4 | F10: Under time pressure, operators over-accept automated outputs (Cummings), so the interface uses deliberately mild wording…
A11: The safeguard's hardest case is created by the bundle's own honesty | B11: System Design | C11: S32, S35, S13 | D11: Support and limitation | E11: 2.4 | F11: Explanations people find useful are contrastive (Miller), so bundles keep the conclusions they rejected; this creates a grounding risk the check must handle…
A12: Threat to validity: the grounding check resolves identifiers, not sentences | B12: Evaluation | C12: S34, S35, S36 | D12: Contrast and limitation | E12: 2.4 | F12: Attribution research judges whether each sentence is supported (Rashkin et al.; Gao et al.); EM Fusion's check resolves identifiers only, so its catch rate is a lower bound…
... A19: Identifier pseudonymisation placed at the DAL | B19: System Design | C19: Find a UK GDPR / ICO source | D19: Chapter 3 ethics | E19: Ch3 | F19: Belongs in ethics and legal issues; source it from ICO guidance rather than the literature review.

Sheet Chapter 3 refs
A1: Reference (Harvard) | B1: Use it for | C1: Checked? | D1: Status
A2: Hevner, A.R., March, S.T., Park, J. and Ram, S. (2004) 'Design science in information systems research', MIS Quarterly, 28(1), pp. 75–105. | B2: Frames the project as design science: build an artefact, then evaluate it. | C2: Verify details | D2: To read
A3: Peffers, K., Tuunanen, T., Rothenberger, M.A. and Chatterjee, S. (2007) 'A design science research methodology for information systems research', Journal of Management Information Systems, 24(3), pp. 45–77. | B3: A step-by-step design science process to structure the methodology section. | C3: Verify details | D3: To read
A4: Wohlin, C. et al. (2012) Experimentation in Software Engineering. Berlin: Springer. | B4: Threats-to-validity categories (conclusion, internal, construct, external) for organising your many recorded threats. | C4: Verify details | D4: To read
A5: Cohen, J. (1968) 'Weighted kappa: nominal scale agreement with provision for scaled disagreement or partial credit', Psychological Bulletin, 70(4), pp. 213–220. | B5: Your quadratic-weighted κ between the two raters. | C5: Verify details | D5: To read
A6: McHugh, M.L. (2012) 'Interrater reliability: the kappa statistic', Biochemia Medica, 22(3), pp. 276–282. | B6: Interpreting κ values, with the caveats about agreement bands. | C6: Verify details | D6: To read
A7: Zheng, L. et al. (2023) 'Judging LLM-as-a-judge with MT-Bench and Chatbot Arena', in Advances in Neural Information Processing Systems 36 (Datasets and Benchmarks). | B7: Why human raters rather than an LLM judge: position, verbosity and self-preference biases. | C7: Verify details | D7: To read
A8: Jia, Y. and Harman, M. (2011) 'An analysis and survey of the development of mutation testing', IEEE Transactions on Software Engineering, 37(5), pp. 649–678. | B8: Your mutation passes (Chapter 3 or 5). | C8: Verify details | D8: To read
A9: Hart, S.G. and Staveland, L.E. (1988) 'Development of NASA-TLX (Task Load Index): results of empirical and theoretical research', Advances in Psychology, 52, pp. 139–183. | B9: Only if you discuss the withdrawn user study and what it would have measured. | C9: Verify details | D9: To read

Sheet Gap searches
A1: Log each search behind your gap statement, so you can say exactly what you searched if an examiner asks.
A2: Date | B2: Database | C2: Query | D2: Results | E2: Relevant hits | F2: What they show / notes
A3: (example) 2026-10-12 | B3: Google Scholar | C3: "ADS-B" "GNSS interference" detection | D3: (e.g. 1,240) | E3: (e.g. 6) | F3: (example) Most use NIC/NACp; none pair detection with generated explanations.
B4: IEEE Xplore | C4: "data fusion" "large language model" "situational awareness"
B5: ACM Digital Library | C5: "hypothesis generation" LLM "decision support" grounding OR attribution
B6: Scopus (via university) | C6: "electromagnetic" "situational awareness" software OR prototype
B7: Google Scholar | C7: "canonical data model" "data fusion" provenance
B8: Google Scholar | C8: "evidence-grounded" OR "citation" LLM defence OR military "decision support"
